<?xml version="1.0" ?>
<robot>
	<macro name="wheel" params="name">
		  <link name="${name}">   
    <visual name="${name}_visual">
      <origin rpy="0 1.5707 1.5707" xyz="0 0 0"/>
      <geometry>
        <cylinder length="0.04" radius="0.1"/>
      </geometry>
      <material name="blue">
        <color rgba="0.2 0.2 1.0 1.0"/>
      </material>      
    </visual> 
    <inertial>
      <mass value="0.2"/>
      <origin rpy="0 1.5707 1.5707" xyz="0 0 0"/>
      <inertia ixx="0.00052666666" ixy="0" ixz="0" iyy="0.00052666666" iyz="0" izz="0.001"/>
    </inertial>
    
    <collision name="right_wheel_collision">
      <origin rpy="0 1.5707 1.5707" xyz="0 0 0" />
      <geometry>
        <cylinder length="0.04" radius="0.1"/>
      </geometry>
    </collision>
  </link>

	</macro>

	<macro name="wheel_hinge" params="name child origin_xyz">
		  <joint name="${name}" type="continuous">
    <origin rpy="0 0 0" xyz="${origin_xyz}"/>
    <child link="${child}" />
    <parent link="base_link_chassis"/>
    <axis rpy="0 0 0" xyz="0 1 0"/>
    <limit effort="10000" velocity="1000"/>
    <joint_properties damping="1.0" friction="1.0" />
  </joint>  

	</macro>
</robot>
